<mujocoinclude model="MUSIC-Hand-v0.15">
              <body name="P:white_key_0" pos="0.6025 0 -0.0105">
              <geom name="P:white_key_0" class="white_key"/>
              <joint name="P:white_joint_0" class="white_key"/>
              </body>
              <body name="P:black_key_1" pos="0.586937 0 0">
              <geom name="P:black_key_1" class="black_key"/>
              <joint name="P:black_joint_1" class="black_key"/>
              </body>
              <body name="P:white_key_2" pos="0.578873 0 -0.0105">
              <geom name="P:white_key_2" class="white_key"/>
              <joint name="P:white_joint_2" class="white_key"/>
              </body>
              <body name="P:white_key_3" pos="0.555246 0 -0.0105">
              <geom name="P:white_key_3" class="white_key"/>
              <joint name="P:white_joint_3" class="white_key"/>
              </body>
              <body name="P:black_key_4" pos="0.545932 0 0">
              <geom name="P:black_key_4" class="black_key"/>
              <joint name="P:black_joint_4" class="black_key"/>
              </body>
              <body name="P:white_key_5" pos="0.531618 0 -0.0105">
              <geom name="P:white_key_5" class="white_key"/>
              <joint name="P:white_joint_5" class="white_key"/>
              </body>
              <body name="P:black_key_6" pos="0.517304 0 0">
              <geom name="P:black_key_6" class="black_key"/>
              <joint name="P:black_joint_6" class="black_key"/>
              </body>
              <body name="P:white_key_7" pos="0.507991 0 -0.0105">
              <geom name="P:white_key_7" class="white_key"/>
              <joint name="P:white_joint_7" class="white_key"/>
              </body>
              <body name="P:white_key_8" pos="0.484363 0 -0.0105">
              <geom name="P:white_key_8" class="white_key"/>
              <joint name="P:white_joint_8" class="white_key"/>
              </body>
              <body name="P:black_key_9" pos="0.476299 0 0">
              <geom name="P:black_key_9" class="black_key"/>
              <joint name="P:black_joint_9" class="black_key"/>
              </body>
              <body name="P:white_key_10" pos="0.460736 0 -0.0105">
              <geom name="P:white_key_10" class="white_key"/>
              <joint name="P:white_joint_10" class="white_key"/>
              </body>
              <body name="P:black_key_11" pos="0.448922 0 0">
              <geom name="P:black_key_11" class="black_key"/>
              <joint name="P:black_joint_11" class="black_key"/>
              </body>
              <body name="P:white_key_12" pos="0.437108 0 -0.0105">
              <geom name="P:white_key_12" class="white_key"/>
              <joint name="P:white_joint_12" class="white_key"/>
              </body>
              <body name="P:black_key_13" pos="0.421544 0 0">
              <geom name="P:black_key_13" class="black_key"/>
              <joint name="P:black_joint_13" class="black_key"/>
              </body>
              <body name="P:white_key_14" pos="0.413481 0 -0.0105">
              <geom name="P:white_key_14" class="white_key"/>
              <joint name="P:white_joint_14" class="white_key"/>
              </body>
              <body name="P:white_key_15" pos="0.389853 0 -0.0105">
              <geom name="P:white_key_15" class="white_key"/>
              <joint name="P:white_joint_15" class="white_key"/>
              </body>
              <body name="P:black_key_16" pos="0.38054 0 0">
              <geom name="P:black_key_16" class="black_key"/>
              <joint name="P:black_joint_16" class="black_key"/>
              </body>
              <body name="P:white_key_17" pos="0.366226 0 -0.0105">
              <geom name="P:white_key_17" class="white_key"/>
              <joint name="P:white_joint_17" class="white_key"/>
              </body>
              <body name="P:black_key_18" pos="0.351912 0 0">
              <geom name="P:black_key_18" class="black_key"/>
              <joint name="P:black_joint_18" class="black_key"/>
              </body>
              <body name="P:white_key_19" pos="0.342598 0 -0.0105">
              <geom name="P:white_key_19" class="white_key"/>
              <joint name="P:white_joint_19" class="white_key"/>
              </body>
              <body name="P:white_key_20" pos="0.318971 0 -0.0105">
              <geom name="P:white_key_20" class="white_key"/>
              <joint name="P:white_joint_20" class="white_key"/>
              </body>
              <body name="P:black_key_21" pos="0.310907 0 0">
              <geom name="P:black_key_21" class="black_key"/>
              <joint name="P:black_joint_21" class="black_key"/>
              </body>
              <body name="P:white_key_22" pos="0.295343 0 -0.0105">
              <geom name="P:white_key_22" class="white_key"/>
              <joint name="P:white_joint_22" class="white_key"/>
              </body>
              <body name="P:black_key_23" pos="0.28353 0 0">
              <geom name="P:black_key_23" class="black_key"/>
              <joint name="P:black_joint_23" class="black_key"/>
              </body>
              <body name="P:white_key_24" pos="0.271716 0 -0.0105">
              <geom name="P:white_key_24" class="white_key"/>
              <joint name="P:white_joint_24" class="white_key"/>
              </body>
              <body name="P:black_key_25" pos="0.256152 0 0">
              <geom name="P:black_key_25" class="black_key"/>
              <joint name="P:black_joint_25" class="black_key"/>
              </body>
              <body name="P:white_key_26" pos="0.248088 0 -0.0105">
              <geom name="P:white_key_26" class="white_key"/>
              <joint name="P:white_joint_26" class="white_key"/>
              </body>
              <body name="P:white_key_27" pos="0.224461 0 -0.0105">
              <geom name="P:white_key_27" class="white_key"/>
              <joint name="P:white_joint_27" class="white_key"/>
              </body>
              <body name="P:black_key_28" pos="0.215147 0 0">
              <geom name="P:black_key_28" class="black_key"/>
              <joint name="P:black_joint_28" class="black_key"/>
              </body>
              <body name="P:white_key_29" pos="0.200833 0 -0.0105">
              <geom name="P:white_key_29" class="white_key"/>
              <joint name="P:white_joint_29" class="white_key"/>
              </body>
              <body name="P:black_key_30" pos="0.18652 0 0">
              <geom name="P:black_key_30" class="black_key"/>
              <joint name="P:black_joint_30" class="black_key"/>
              </body>
              <body name="P:white_key_31" pos="0.177206 0 -0.0105">
              <geom name="P:white_key_31" class="white_key"/>
              <joint name="P:white_joint_31" class="white_key"/>
              </body>
              <body name="P:white_key_32" pos="0.153579 0 -0.0105">
              <geom name="P:white_key_32" class="white_key"/>
              <joint name="P:white_joint_32" class="white_key"/>
              </body>
              <body name="P:black_key_33" pos="0.145515 0 0">
              <geom name="P:black_key_33" class="black_key"/>
              <joint name="P:black_joint_33" class="black_key"/>
              </body>
              <body name="P:white_key_34" pos="0.129951 0 -0.0105">
              <geom name="P:white_key_34" class="white_key"/>
              <joint name="P:white_joint_34" class="white_key"/>
              </body>
              <body name="P:black_key_35" pos="0.118137 0 0">
              <geom name="P:black_key_35" class="black_key"/>
              <joint name="P:black_joint_35" class="black_key"/>
              </body>
              <body name="P:white_key_36" pos="0.106324 0 -0.0105">
              <geom name="P:white_key_36" class="white_key"/>
              <joint name="P:white_joint_36" class="white_key"/>
              </body>
              <body name="P:black_key_37" pos="0.09076 0 0">
              <geom name="P:black_key_37" class="black_key"/>
              <joint name="P:black_joint_37" class="black_key"/>
              </body>
              <body name="P:white_key_38" pos="0.082696 0 -0.0105">
              <geom name="P:white_key_38" class="white_key"/>
              <joint name="P:white_joint_38" class="white_key"/>
              </body>
              <body name="P:white_key_39" pos="0.059069 0 -0.0105">
              <geom name="P:white_key_39" class="white_key"/>
              <joint name="P:white_joint_39" class="white_key"/>
              </body>
              <body name="P:black_key_40" pos="0.049755 0 0">
              <geom name="P:black_key_40" class="black_key"/>
              <joint name="P:black_joint_40" class="black_key"/>
              </body>
              <body name="P:white_key_41" pos="0.035441 0 -0.0105">
              <geom name="P:white_key_41" class="white_key"/>
              <joint name="P:white_joint_41" class="white_key"/>
              </body>
              <body name="P:black_key_42" pos="0.021127 0 0">
              <geom name="P:black_key_42" class="black_key"/>
              <joint name="P:black_joint_42" class="black_key"/>
              </body>
              <body name="P:white_key_43" pos="0.011814 0 -0.0105">
              <geom name="P:white_key_43" class="white_key"/>
              <joint name="P:white_joint_43" class="white_key"/>
              </body>
              <body name="P:white_key_44" pos="-0.011814 0 -0.0105">
              <geom name="P:white_key_44" class="white_key"/>
              <joint name="P:white_joint_44" class="white_key"/>
              </body>
              <body name="P:black_key_45" pos="-0.019877 0 0">
              <geom name="P:black_key_45" class="black_key"/>
              <joint name="P:black_joint_45" class="black_key"/>
              </body>
              <body name="P:white_key_46" pos="-0.035441 0 -0.0105">
              <geom name="P:white_key_46" class="white_key"/>
              <joint name="P:white_joint_46" class="white_key"/>
              </body>
              <body name="P:black_key_47" pos="-0.047255 0 0">
              <geom name="P:black_key_47" class="black_key"/>
              <joint name="P:black_joint_47" class="black_key"/>
              </body>
              <body name="P:white_key_48" pos="-0.059069 0 -0.0105">
              <geom name="P:white_key_48" class="white_key"/>
              <joint name="P:white_joint_48" class="white_key"/>
              </body>
              <body name="P:black_key_49" pos="-0.074632 0 0">
              <geom name="P:black_key_49" class="black_key"/>
              <joint name="P:black_joint_49" class="black_key"/>
              </body>
              <body name="P:white_key_50" pos="-0.082696 0 -0.0105">
              <geom name="P:white_key_50" class="white_key"/>
              <joint name="P:white_joint_50" class="white_key"/>
              </body>
              <body name="P:white_key_51" pos="-0.106324 0 -0.0105">
              <geom name="P:white_key_51" class="white_key"/>
              <joint name="P:white_joint_51" class="white_key"/>
              </body>
              <body name="P:black_key_52" pos="-0.115637 0 0">
              <geom name="P:black_key_52" class="black_key"/>
              <joint name="P:black_joint_52" class="black_key"/>
              </body>
              <body name="P:white_key_53" pos="-0.129951 0 -0.0105">
              <geom name="P:white_key_53" class="white_key"/>
              <joint name="P:white_joint_53" class="white_key"/>
              </body>
              <body name="P:black_key_54" pos="-0.144265 0 0">
              <geom name="P:black_key_54" class="black_key"/>
              <joint name="P:black_joint_54" class="black_key"/>
              </body>
              <body name="P:white_key_55" pos="-0.153579 0 -0.0105">
              <geom name="P:white_key_55" class="white_key"/>
              <joint name="P:white_joint_55" class="white_key"/>
              </body>
              <body name="P:white_key_56" pos="-0.177206 0 -0.0105">
              <geom name="P:white_key_56" class="white_key"/>
              <joint name="P:white_joint_56" class="white_key"/>
              </body>
              <body name="P:black_key_57" pos="-0.18527 0 0">
              <geom name="P:black_key_57" class="black_key"/>
              <joint name="P:black_joint_57" class="black_key"/>
              </body>
              <body name="P:white_key_58" pos="-0.200833 0 -0.0105">
              <geom name="P:white_key_58" class="white_key"/>
              <joint name="P:white_joint_58" class="white_key"/>
              </body>
              <body name="P:black_key_59" pos="-0.212647 0 0">
              <geom name="P:black_key_59" class="black_key"/>
              <joint name="P:black_joint_59" class="black_key"/>
              </body>
              <body name="P:white_key_60" pos="-0.224461 0 -0.0105">
              <geom name="P:white_key_60" class="white_key"/>
              <joint name="P:white_joint_60" class="white_key"/>
              </body>
              <body name="P:black_key_61" pos="-0.240025 0 0">
              <geom name="P:black_key_61" class="black_key"/>
              <joint name="P:black_joint_61" class="black_key"/>
              </body>
              <body name="P:white_key_62" pos="-0.248088 0 -0.0105">
              <geom name="P:white_key_62" class="white_key"/>
              <joint name="P:white_joint_62" class="white_key"/>
              </body>
              <body name="P:white_key_63" pos="-0.271716 0 -0.0105">
              <geom name="P:white_key_63" class="white_key"/>
              <joint name="P:white_joint_63" class="white_key"/>
              </body>
              <body name="P:black_key_64" pos="-0.28103 0 0">
              <geom name="P:black_key_64" class="black_key"/>
              <joint name="P:black_joint_64" class="black_key"/>
              </body>
              <body name="P:white_key_65" pos="-0.295343 0 -0.0105">
              <geom name="P:white_key_65" class="white_key"/>
              <joint name="P:white_joint_65" class="white_key"/>
              </body>
              <body name="P:black_key_66" pos="-0.309657 0 0">
              <geom name="P:black_key_66" class="black_key"/>
              <joint name="P:black_joint_66" class="black_key"/>
              </body>
              <body name="P:white_key_67" pos="-0.318971 0 -0.0105">
              <geom name="P:white_key_67" class="white_key"/>
              <joint name="P:white_joint_67" class="white_key"/>
              </body>
              <body name="P:white_key_68" pos="-0.342598 0 -0.0105">
              <geom name="P:white_key_68" class="white_key"/>
              <joint name="P:white_joint_68" class="white_key"/>
              </body>
              <body name="P:black_key_69" pos="-0.350662 0 0">
              <geom name="P:black_key_69" class="black_key"/>
              <joint name="P:black_joint_69" class="black_key"/>
              </body>
              <body name="P:white_key_70" pos="-0.366226 0 -0.0105">
              <geom name="P:white_key_70" class="white_key"/>
              <joint name="P:white_joint_70" class="white_key"/>
              </body>
              <body name="P:black_key_71" pos="-0.37804 0 0">
              <geom name="P:black_key_71" class="black_key"/>
              <joint name="P:black_joint_71" class="black_key"/>
              </body>
              <body name="P:white_key_72" pos="-0.389853 0 -0.0105">
              <geom name="P:white_key_72" class="white_key"/>
              <joint name="P:white_joint_72" class="white_key"/>
              </body>
              <body name="P:black_key_73" pos="-0.405417 0 0">
              <geom name="P:black_key_73" class="black_key"/>
              <joint name="P:black_joint_73" class="black_key"/>
              </body>
              <body name="P:white_key_74" pos="-0.413481 0 -0.0105">
              <geom name="P:white_key_74" class="white_key"/>
              <joint name="P:white_joint_74" class="white_key"/>
              </body>
              <body name="P:white_key_75" pos="-0.437108 0 -0.0105">
              <geom name="P:white_key_75" class="white_key"/>
              <joint name="P:white_joint_75" class="white_key"/>
              </body>
              <body name="P:black_key_76" pos="-0.446422 0 0">
              <geom name="P:black_key_76" class="black_key"/>
              <joint name="P:black_joint_76" class="black_key"/>
              </body>
              <body name="P:white_key_77" pos="-0.460736 0 -0.0105">
              <geom name="P:white_key_77" class="white_key"/>
              <joint name="P:white_joint_77" class="white_key"/>
              </body>
              <body name="P:black_key_78" pos="-0.475049 0 0">
              <geom name="P:black_key_78" class="black_key"/>
              <joint name="P:black_joint_78" class="black_key"/>
              </body>
              <body name="P:white_key_79" pos="-0.484363 0 -0.0105">
              <geom name="P:white_key_79" class="white_key"/>
              <joint name="P:white_joint_79" class="white_key"/>
              </body>
              <body name="P:white_key_80" pos="-0.507991 0 -0.0105">
              <geom name="P:white_key_80" class="white_key"/>
              <joint name="P:white_joint_80" class="white_key"/>
              </body>
              <body name="P:black_key_81" pos="-0.516054 0 0">
              <geom name="P:black_key_81" class="black_key"/>
              <joint name="P:black_joint_81" class="black_key"/>
              </body>
              <body name="P:white_key_82" pos="-0.531618 0 -0.0105">
              <geom name="P:white_key_82" class="white_key"/>
              <joint name="P:white_joint_82" class="white_key"/>
              </body>
              <body name="P:black_key_83" pos="-0.543432 0 0">
              <geom name="P:black_key_83" class="black_key"/>
              <joint name="P:black_joint_83" class="black_key"/>
              </body>
              <body name="P:white_key_84" pos="-0.555246 0 -0.0105">
              <geom name="P:white_key_84" class="white_key"/>
              <joint name="P:white_joint_84" class="white_key"/>
              </body>
              <body name="P:black_key_85" pos="-0.570809 0 0">
              <geom name="P:black_key_85" class="black_key"/>
              <joint name="P:black_joint_85" class="black_key"/>
              </body>
              <body name="P:white_key_86" pos="-0.578873 0 -0.0105">
              <geom name="P:white_key_86" class="white_key"/>
              <joint name="P:white_joint_86" class="white_key"/>
              </body>
              <body name="P:white_key_87" pos="-0.6025 0 -0.0105">
              <geom name="P:white_key_87" class="white_key"/>
              <joint name="P:white_joint_87" class="white_key"/>
              </body>
    
              <!-- 17mm below the white key surface -->
              <geom name="P:bottom_frame" type="box" pos="0 0.074 -0.0275" size="0.63 0.08 0.0105" contype="0" conaffinity="0" />
    
</mujocoinclude>